Workbook
Name GeocodeAddressColumn_Oct20ScreenshotAddress: #REF!
Name GeocodeAddressColumn_GoodTableCapture: 'Good Table Capture'!$E$1

Sheet Good Table Live
A1: Restaurant Link and Name | B1: Price Range | C1: Price Range Values | D1: Payment Methods | E1: Address | F1: Images | G1: Ratings | H1: Rating Number Estimate
A2: =IFERROR(__xludf.DUMMYFUNCTION("IMPORTXML('URLs and Paths'!B1,'URLs and Paths'!B3)"),"https://www.restomontreal.ca/resto/sham-mont-royal-montreal/18037/en/") -> https://www.restomontreal.ca/resto/sham-mont-royal-montreal/18037/en/
A3: =IFERROR(__xludf.DUMMYFUNCTION("""COMPUTED_VALUE""")," Sham Mont-Royal ") -> Sham Mont-Royal | B3: =IFERROR(__xludf.DUMMYFUNCTION("IMPORTXML(A2,'URLs and Paths'!$B$4)"),"$$") -> $$ | C3: =IFS(B3="$", 10, B3="$$", 25, B3="$$$", 37.5, B3="$ & $$", 17.5, B3="$ & $$$", 23.75, B3="$$ & $$$", 31.25 ) -> 25 | D3: =IFERROR(__xludf.DUMMYFUNCTION("IMPORTXML(A2,'URLs and Paths'!$B$5)")," Master Card, Visa, AMEX, Interac, Mobile Payment, Contactless Payment") -> Master Card, Visa, AMEX, Interac, Mobile Payment, Contactless Payment | E3: =IFERROR(__xludf.DUMMYFUNCTION("IMPORTXML(A2,'URLs and Paths'!$B$6)"),"1371 Avenue Mont-Royal E, Montreal, H2J 1Y8") -> 1371 Avenue Mont-Royal E, Montreal, H2J 1Y8 | F3: =IFERROR(__xludf.DUMMYFUNCTION("IMAGE(IMPORTXML(A2,'URLs and Paths'!$B$7))"),"") | G3: =TEXTJOIN(",",TRUE,A4:A8) -> fas fa-star search star-rating,fas fa-star search star-rating,fas fa-star search star-rating,fas fa-star search star-rating,fas fa-star search star-rating | H3: =IFS(G3 = 'URLs and Paths'!$D$3,5, G3='URLs and Paths'!$D$4, 4.5, G3='URLs and Paths'!$D$5, 4, G3='URLs and Paths'!$D$6, 3.5, G3='URLs and Paths'!$D$7, 3, G3='URLs and Paths'!$D$8, 2.5, G3='URLs and Paths'!$D$9, 2, G3='URLs and Paths'!$D$10, 1.5, G3='URLs and Paths'!$D$11, 1) -> 5
A4: =IFERROR(__xludf.DUMMYFUNCTION("""COMPUTED_VALUE"""),"fas fa-star search star-rating") -> fas fa-star search star-rating
A5: =IFERROR(__xludf.DUMMYFUNCTION("""COMPUTED_VALUE"""),"fas fa-star search star-rating") -> fas fa-star search star-rating
A6: =IFERROR(__xludf.DUMMYFUNCTION("""COMPUTED_VALUE"""),"fas fa-star search star-rating") -> fas fa-star search star-rating
A7: =IFERROR(__xludf.DUMMYFUNCTION("""COMPUTED_VALUE"""),"fas fa-star search star-rating") -> fas fa-star search star-rating
A8: =IFERROR(__xludf.DUMMYFUNCTION("""COMPUTED_VALUE"""),"fas fa-star search star-rating") -> fas fa-star search star-rating
A9: =IFERROR(__xludf.DUMMYFUNCTION("""COMPUTED_VALUE"""),"https://www.restomontreal.ca/resto/le-mekong-montreal/12927/en/") -> https://www.restomontreal.ca/resto/le-mekong-montreal/12927/en/
A10: =IFERROR(__xludf.DUMMYFUNCTION("""COMPUTED_VALUE""")," Le Mekong ") -> Le Mekong | B10: =IFERROR(__xludf.DUMMYFUNCTION("IMPORTXML(A9,'URLs and Paths'!$B$4)"),"$ & $$") -> $ & $$ | C10: =IFS(B10="$", 10, B10="$$", 25, B10="$$$", 37.5, B10="$ & $$", 17.5, B10="$ & $$$", 23.75, B10="$$ & $$$", 31.25 ) -> 17.5 | D10: =IFERROR(__xludf.DUMMYFUNCTION("IMPORTXML(A9,'URLs and Paths'!$B$5)"),"Loading...") -> Loading... | E10: =IFERROR(__xludf.DUMMYFUNCTION("IMPORTXML(A9,'URLs and Paths'!$B$6)"),"921 Avenue Mont-Royal E, Montreal, H2J 1X3") -> 921 Avenue Mont-Royal E, Montreal, H2J 1X3 | F10: =IFERROR(__xludf.DUMMYFUNCTION("IMAGE(IMPORTXML(A9,'URLs and Paths'!$B$7))"),"") | G10: =TEXTJOIN(",",TRUE,A11:A15) -> fas fa-star search star-rating,fas fa-star search star-rating,fas fa-star search star-rating,fas fa-star search star-rating,fas fa-star-half search star-rating | H10: =IFS(G10 = 'URLs and Paths'!$D$3,5, G10='URLs and Paths'!$D$4, 4.5, G10='URLs and Paths'!$D$5, 4, G10='URLs and Paths'!$D$6, 3.5, G10='URLs and Paths'!$D$7, 3, G10='URLs and Paths'!$D$8, 2.5, G10='URLs and Paths'!$D$9, 2, G10='URLs and Paths'!$D$10, 1.5, G10='URLs and Paths'!$D$11, 1) -> 4.5
A11: =IFERROR(__xludf.DUMMYFUNCTION("""COMPUTED_VALUE"""),"fas fa-star search star-rating") -> fas fa-star search star-rating
A12: =IFERROR(__xludf.DUMMYFUNCTION("""COMPUTED_VALUE"""),"fas fa-star search star-rating") -> fas fa-star search star-rating
A13: =IFERROR(__xludf.DUMMYFUNCTION("""COMPUTED_VALUE"""),"fas fa-star search star-rating") -> fas fa-star search star-rating
A14: =IFERROR(__xludf.DUMMYFUNCTION("""COMPUTED_VALUE"""),"fas fa-star search star-rating") -> fas fa-star search star-rating
A15: =IFERROR(__xludf.DUMMYFUNCTION("""COMPUTED_VALUE"""),"fas fa-star-half search star-rating") -> fas fa-star-half search star-rating
A16: =IFERROR(__xludf.DUMMYFUNCTION("""COMPUTED_VALUE"""),"https://www.restomontreal.ca/resto/viva-restaurant-bar-montreal/17184/en/") -> https://www.restomontreal.ca/resto/viva-restaurant-bar-montreal/17184/en/
A17: =IFERROR(__xludf.DUMMYFUNCTION("""COMPUTED_VALUE""")," Viva Restaurant + Bar ") -> Viva Restaurant + Bar | B17: =IFERROR(__xludf.DUMMYFUNCTION("IMPORTXML(A16,'URLs and Paths'!$B$4)"),"$$ & $$$") -> $$ & $$$ | C17: =IFS(B17="$", 10, B17="$$", 25, B17="$$$", 37.5, B17="$ & $$", 17.5, B17="$ & $$$", 23.75, B17="$$ & $$$", 31.25 ) -> 31.25 | D17: =IFERROR(__xludf.DUMMYFUNCTION("IMPORTXML(A16,'URLs and Paths'!$B$5)")," Master Card, Visa, Interac, Mobile Payment, Contactless Payment") -> Master Card, Visa, Interac, Mobile Payment, Contactless Payment | E17: =IFERROR(__xludf.DUMMYFUNCTION("IMPORTXML(A16,'URLs and Paths'!$B$6)"),"107 Rue Rachel E, Montreal, H2W 1C8") -> 107 Rue Rachel E, Montreal, H2W 1C8 | F17: =IFERROR(__xludf.DUMMYFUNCTION("IMAGE(IMPORTXML(A16,'URLs and Paths'!$B$7))"),"") | G17: =TEXTJOIN(",",TRUE,A18:A22) -> fas fa-star search star-rating,fas fa-star search star-rating,fas fa-star search star-rating,fas fa-star search star-rating,fas fa-star search star-rating | H17: =IFS(G17 = 'URLs and Paths'!$D$3,5, G17='URLs and Paths'!$D$4, 4.5, G17='URLs and Paths'!$D$5, 4, G17='URLs and Paths'!$D$6, 3.5, G17='URLs and Paths'!$D$7, 3, G17='URLs and Paths'!$D$8, 2.5, G17='URLs and Paths'!$D$9, 2, G17='URLs and Paths'!$D$10, 1.5, G17='URLs and Paths'!$D$11, 1) -> 5
A18: =IFERROR(__xludf.DUMMYFUNCTION("""COMPUTED_VALUE"""),"fas fa-star search star-rating") -> fas fa-star search star-rating
A19: =IFERROR(__xludf.DUMMYFUNCTION("""COMPUTED_VALUE"""),"fas fa-star search star-rating") -> fas fa-star search star-rating
A20: =IFERROR(__xludf.DUMMYFUNCTION("""COMPUTED_VALUE"""),"fas fa-star search star-rating") -> fas fa-star search star-rating
A21: =IFERROR(__xludf.DUMMYFUNCTION("""COMPUTED_VALUE"""),"fas fa-star search star-rating") -> fas fa-star search star-rating
A22: =IFERROR(__xludf.DUMMYFUNCTION("""COMPUTED_VALUE"""),"fas fa-star search star-rating") -> fas fa-star search star-rating
A23: =IFERROR(__xludf.DUMMYFUNCTION("""COMPUTED_VALUE"""),"https://www.restomontreal.ca/resto/chez-doval-montreal/1547/en/") -> https://www.restomontreal.ca/resto/chez-doval-montreal/1547/en/
A24: =IFERROR(__xludf.DUMMYFUNCTION("""COMPUTED_VALUE""")," Chez Doval ") -> Chez Doval | B24: =IFERROR(__xludf.DUMMYFUNCTION("IMPORTXML(A23,'URLs and Paths'!$B$4)"),"Loading...") -> Loading... | C24: =IFS(B24="$", 10, B24="$$", 25, B24="$$$", 37.5, B24="$ & $$", 17.5, B24="$ & $$$", 23.75, B24="$$ & $$$", 31.25 ) -> Loading... | D24: =IFERROR(__xludf.DUMMYFUNCTION("IMPORTXML(A23,'URLs and Paths'!$B$5)"),"Loading...") -> Loading... | E24: =IFERROR(__xludf.DUMMYFUNCTION("IMPORTXML(A23,'URLs and Paths'!$B$6)"),"Loading...") -> Loading... | F24: =IFERROR(__xludf.DUMMYFUNCTION("IMAGE(IMPORTXML(A23,'URLs and Paths'!$B$7))"),"Loading...") -> Loading... | G24: =TEXTJOIN(",",TRUE,A25:A29) -> fas fa-star search star-rating,fas fa-star search star-rating,fas fa-star search star-rating,fas fa-star search star-rating,fas fa-star-half search star-rating | H24: =IFS(G24 = 'URLs and Paths'!$D$3,5, G24='URLs and Paths'!$D$4, 4.5, G24='URLs and Paths'!$D$5, 4, G24='URLs and Paths'!$D$6, 3.5, G24='URLs and Paths'!$D$7, 3, G24='URLs and Paths'!$D$8, 2.5, G24='URLs and Paths'!$D$9, 2, G24='URLs and Paths'!$D$10, 1.5, G24='URLs and Paths'!$D$11, 1) -> 4.5
A25: =IFERROR(__xludf.DUMMYFUNCTION("""COMPUTED_VALUE"""),"fas fa-star search star-rating") -> fas fa-star search star-rating
A26: =IFERROR(__xludf.DUMMYFUNCTION("""COMPUTED_VALUE"""),"fas fa-star search star-rating") -> fas fa-star search star-rating
A27: =IFERROR(__xludf.DUMMYFUNCTION("""COMPUTED_VALUE"""),"fas fa-star search star-rating") -> fas fa-star search star-rating
A28: =IFERROR(__xludf.DUMMYFUNCTION("""COMPUTED_VALUE"""),"fas fa-star search star-rating") -> fas fa-star search star-rating
A29: =IFERROR(__xludf.DUMMYFUNCTION("""COMPUTED_VALUE"""),"fas fa-star-half search star-rating") -> fas fa-star-half search star-rating
A30: =IFERROR(__xludf.DUMMYFUNCTION("""COMPUTED_VALUE"""),"https://www.restomontreal.ca/resto/cuisine-pronto-mtl-montreal/10534/en/") -> https://www.restomontreal.ca/resto/cuisine-pronto-mtl-montreal/10534/en/
A31: =IFERROR(__xludf.DUMMYFUNCTION("""COMPUTED_VALUE""")," Cuisine Pronto MTL ") -> Cuisine Pronto MTL | B31: =IFERROR(__xludf.DUMMYFUNCTION("IMPORTXML(A30,'URLs and Paths'!$B$4)"),"Loading...") -> Loading... | C31: =IFS(B31="$", 10, B31="$$", 25, B31="$$$", 37.5, B31="$ & $$", 17.5, B31="$ & $$$", 23.75, B31="$$ & $$$", 31.25 ) -> Loading... | D31: =IFERROR(__xludf.DUMMYFUNCTION("IMPORTXML(A30,'URLs and Paths'!$B$5)"),"Loading...") -> Loading... | E31: =IFERROR(__xludf.DUMMYFUNCTION("IMPORTXML(A30,'URLs and Paths'!$B$6)"),"2025 Avenue Mont-Royal E, Montreal, H2H 1J7") -> 2025 Avenue Mont-Royal E, Montreal, H2H 1J7 | F31: =IFERROR(__xludf.DUMMYFUNCTION("IMAGE(IMPORTXML(A30,'URLs and Paths'!$B$7))"),"Loading...") -> Loading... | G31: =TEXTJOIN(",",TRUE,A32:A36) -> fas fa-star search star-rating,fas fa-star search star-rating,fas fa-star search star-rating,fas fa-star search star-rating,fas fa-star-half search star-rating | H31: =IFS(G31 = 'URLs and Paths'!$D$3,5, G31='URLs and Paths'!$D$4, 4.5, G31='URLs and Paths'!$D$5, 4, G31='URLs and Paths'!$D$6, 3.5, G31='URLs and Paths'!$D$7, 3, G31='URLs and Paths'!$D$8, 2.5, G31='URLs and Paths'!$D$9, 2, G31='URLs and Paths'!$D$10, 1.5, G31='URLs and Paths'!$D$11, 1) -> 4.5
A32: =IFERROR(__xludf.DUMMYFUNCTION("""COMPUTED_VALUE"""),"fas fa-star search star-rating") -> fas fa-star search star-rating
A33: =IFERROR(__xludf.DUMMYFUNCTION("""COMPUTED_VALUE"""),"fas fa-star search star-rating") -> fas fa-star search star-rating
A34: =IFERROR(__xludf.DUMMYFUNCTION("""COMPUTED_VALUE"""),"fas fa-star search star-rating") -> fas fa-star search star-rating
A35: =IFERROR(__xludf.DUMMYFUNCTION("""COMPUTED_VALUE"""),"fas fa-star search star-rating") -> fas fa-star search star-rating
A36: =IFERROR(__xludf.DUMMYFUNCTION("""COMPUTED_VALUE"""),"fas fa-star-half search star-rating") -> fas fa-star-half search star-rating
A37: =IFERROR(__xludf.DUMMYFUNCTION("""COMPUTED_VALUE"""),"https://www.restomontreal.ca/resto/le-virunga-montreal/10928/en/") -> https://www.restomontreal.ca/resto/le-virunga-montreal/10928/en/
A38: =IFERROR(__xludf.DUMMYFUNCTION("""COMPUTED_VALUE""")," Le Virunga ") -> Le Virunga | B38: =IFERROR(__xludf.DUMMYFUNCTION("IMPORTXML(A37,'URLs and Paths'!$B$4)"),"Loading...") -> Loading... | C38: =IFS(B38="$", 10, B38="$$", 25, B38="$$$", 37.5, B38="$ & $$", 17.5, B38="$ & $$$", 23.75, B38="$$ & $$$", 31.25 ) -> Loading... | D38: =IFERROR(__xludf.DUMMYFUNCTION("IMPORTXML(A37,'URLs and Paths'!$B$5)"),"Loading...") -> Loading... | E38: =IFERROR(__xludf.DUMMYFUNCTION("IMPORTXML(A37,'URLs and Paths'!$B$6)"),"Loading...") -> Loading... | F38: =IFERROR(__xludf.DUMMYFUNCTION("IMAGE(IMPORTXML(A37,'URLs and Paths'!$B$7))"),"Loading...") -> Loading... | G38: =TEXTJOIN(",",TRUE,A39:A43) -> fas fa-star search star-rating,fas fa-star search star-rating,fas fa-star search star-rating,fas fa-star search star-rating,fas fa-star search star-rating | H38: =IFS(G38 = 'URLs and Paths'!$D$3,5, G38='URLs and Paths'!$D$4, 4.5, G38='URLs and Paths'!$D$5, 4, G38='URLs and Paths'!$D$6, 3.5, G38='URLs and Paths'!$D$7, 3, G38='URLs and Paths'!$D$8, 2.5, G38='URLs and Paths'!$D$9, 2, G38='URLs and Paths'!$D$10, 1.5, G38='URLs and Paths'!$D$11, 1) -> 5
A39: =IFERROR(__xludf.DUMMYFUNCTION("""COMPUTED_VALUE"""),"fas fa-star search star-rating") -> fas fa-star search star-rating
A40: =IFERROR(__xludf.DUMMYFUNCTION("""COMPUTED_VALUE"""),"fas fa-star search star-rating") -> fas fa-star search star-rating
...

Sheet URLs and Paths
A1: General URL: | B1: https://www.restomontreal.ca/restaurants/?q=le-plateau&d=22&lang=en
D2: Possible Star Rating Output Combinations | E2: Translated Numerical Value
A3: Restaurant Names, URLs, and Star Ratings: | B3: //div[@class='search-result']//span[contains(@id, 'searchname')]/a/text()|//div[@class='search-result']//span[contains(@id, 'searchname')]/a/@href|//div[@class='search-result']//span[contains(@class,'star-rating')]/@class | D3: fas fa-star search star-rating,fas fa-star search star-rating,fas fa-star search star-rating,fas fa-star search star-rating,fas fa-star search star-rating | E3: 5
A4: Restaurant Price Range: | B4: //*[@id="restaurant-profile"]/div[2]/div/div[1]/div[1]/div/div[1]/div/div[2]/div[1]//span[@class="restaurant-price"]/text() | D4: fas fa-star search star-rating,fas fa-star search star-rating,fas fa-star search star-rating,fas fa-star search star-rating,fas fa-star-half search star-rating | E4: 4.5
A5: Payment Methods: | B5: //*[@id="restaurant-profile"]/div[2]/div/div[1]/div[3]/span[@class="mb10 fs-small"]/text() | D5: fas fa-star search star-rating,fas fa-star search star-rating,fas fa-star search star-rating,fas fa-star search star-rating,fal fa-star star-rating | E5: 4
A6: Address: | B6: //*[@id="directions-tracker-2"]/span/text() | D6: fas fa-star search star-rating,fas fa-star search star-rating,fas fa-star search star-rating,fas fa-star-half search star-rating,fal fa-star star-rating | E6: 3.5
A7: Images: | B7: //*[@id="restaurant-profile"]/div[2]/div/div[1]/div[1]/div/div[1]/div/div[2]/div[2]/a/img/@data-src | D7: fas fa-star search star-rating,fas fa-star search star-rating,fas fa-star search star-rating,fal fa-star star-rating,fal fa-star star-rating | E7: 3
D8: fas fa-star search star-rating,fas fa-star search star-rating,fas fa-star-half search star-rating,fal fa-star star-rating,fal fa-star star-rating | E8: 2.5
D9: fas fa-star search star-rating,fas fa-star search star-rating,fal fa-star star-rating,fal fa-star star-rating,fal fa-star star-rating | E9: 2
D10: fas fa-star search star-rating,fas fa-star-half search star-rating,fal fa-star star-rating,fal fa-star star-rating,fal fa-star star-rating | E10: 1.5
D11: fas fa-star search star-rating,fal fa-star star-rating,fal fa-star star-rating,fal fa-star star-rating,fal fa-star star-rating | E11: 1
A12: Step-By-Step: | B12: Step 1) - Extract the unique restaurant names, URLs, and star ratings for each establishment listed on the main website page. - These restaurants were filtered to the Plateau Region. - The General URlL and Retaurant Names, URLs, and Star Ratings query were used (created using the inspect and copy XPath commands on our computers)
B13: Step 2) - In a new “Price Range” column, the price range icons were then scraped using the freshly extracted unique restaurant URL and “Restaurant Price Range” query above. - This output provided information formatted like $$$.
B14: Step 3) - In a new “Price Range Value Column", the price range icons were then translated to an approximate monetary value (CAD). - To do this, an IFS expression was used to evaluate multiple conditions. | C14: Step 3 IFS Equation: IFS(B3="$", 10, B3="$$", 25, B3="$$$", 37.5, B3="$ & $$", 17.5, B3="$ & $$$", 23.75, B3="$$ & $$$", 31.25)
B15: Step 4) - In a new “Payment Methods” column, the accepted forms of payment were listed. - To scrape this data, the unique restaurant URL and Payment Methods query were utilized.
B16: Step 5) - In a new “Address” column, the address, city, and postal code of each restaurant was scrapped. - These cells used the unique restaurant URLs and the “Address” query.
B17: Step 6) - In a new “Images” column, the logo graphics for each restaurant was extracted. - These cells used the unique restaurant URLs and the “Images” query. - To display the images within the google sheet, the function IMAGE was wrapped around the IMPORTXML function. | C17: IMAGE(IMPORTXML())
B18: Step 7) - In a new "Ratings" column, the star ratings extracted in step 1 were reformatted using the TEXTJOIN function. | C18: TEXTJOIN(",", TRUE, CELLS)
B19: Step 8) - In a new “Rating Number Estimate” column, the results of step 7 were assigned a value using the IFS function. - Text within the cells of step 7 were compared to those in cells D3:D11 on this sheet | C19: Step 8 IFS Equation: IFS(G3 = 'URLs and Paths'!$D$3,5, G3='URLs and Paths'!$D$4, 4.5, G3='URLs and Paths'!$D$5, 4, G3='URLs and Paths'!$D$6, 3.5, G3='URLs and Paths'!$D$7, 3, G3='URLs and Paths'!$D$8, 2.5, G3='URLs and Paths'!$D$9, 2, G3='URLs and Paths'!$D$10, 1.5, G3='URLs and Paths'!$D$11, 1)
D39: =IFERROR(__xludf.DUMMYFUNCTION("TEXTJOIN("","", TRUE, IMPORTXML(B1,B8))"),"#VALUE!") -> #VALUE!

Sheet Good Table Capture
A1: Restaurant Names | B1: Price Range | C1: Price Range Values | D1: Payment Methods | E1: Address | F1: Latitude | G1: Longitude | H1: Logos | I1: Rating Value
A2: https://www.restomontreal.ca/resto/caribou-gourmand-montreal/10879/en/
A3: Caribou Gourmand | B3: $$ & $$$ | C3: 31.25 | D3: Master Card, Visa, Interac | E3: 5308 Boulevard St-Laurent, Montreal, H2T 1S1 | F3: 45.524438 | G3: -73.596378 | I3: 4.5
A4: https://www.restomontreal.ca/resto/thailande-montreal/1741/en/
A5: Thailande | B5: $$ | C5: 25 | D5: Master Card, Visa, AMEX, Interac | E5: 88 Avenue Bernard O, Montreal, H2T 2J8 | F5: 45.526256 | G5: -73.602985 | I5: 4.5
A6: https://www.restomontreal.ca/resto/josephine-montreal/12440/en/
A7: Joséphine | B7: $$ & $$$ | C7: 31.25 | D7: Master Card, Visa, AMEX, Interac | E7: 4007 Rue Saint-Denis, Montreal, H2W 2M4 | F7: 45.520846 | G7: -73.575569 | I7: 5
A8: https://www.restomontreal.ca/resto/bistro-co-ut-montreal/13205/en/
A9: Bistro CO ÚT | B9: $ & $$ | C9: 17.5 | D9: Master Card, Visa, AMEX, Interac | E9: 3807 Rue St-André, Montreal, H2L 3V9 | F9: 45.521892 | G9: -73.570211 | I9: 5
A10: https://www.restomontreal.ca/resto/la-belle-coree-montreal/12815/en/
A11: La Belle Corée | B11: $ | C11: 10 | D11: Master Card, Visa, Interac | E11: 101 Avenue Fairmount O., Montreal, H2T 2M4 | F11: 45.52262 | G11: -73.595842 | I11: 4.5
A12: https://www.restomontreal.ca/resto/sham-mont-royal-montreal/18037/en/
A13: Sham Mont-Royal | B13: $$ | C13: 25 | D13: Master Card, Visa, AMEX, Interac, Mobile Payment, Contactless Payment | E13: 1371 Avenue Mont-Royal E, Montreal, H2J 1Y8 | F13: 45.530606 | G13: -73.577013 | I13: 5
A14: https://www.restomontreal.ca/resto/la-maison-grecque-montreal/1288/en/
A15: La Maison Grecque | B15: $$ | C15: 25 | D15: Master Card, Visa, Interac | E15: 450 Avenue Duluth E, Montreal, H2L 1A5 | F15: 45.521371 | G15: -73.575149 | I15: 4.5
A16: https://www.restomontreal.ca/resto/la-petite-marche-montreal/1099/en/
A17: La Petite Marche | B17: $ & $$ | C17: 17.5 | D17: Master Card, Visa, Interac | E17: 5035 Rue Saint-Denis, Montreal, H2J 2L9 | F17: 45.526746 | G17: -73.588648 | I17: 4.5
A18: https://www.restomontreal.ca/resto/zeez-montreal/17534/en/
A19: ZEEZ | B19: $ | C19: 10 | D19: Master Card, Visa, AMEX, Interac, Mobile Payment, Contactless Payment | E19: 19 Avenue Mont-Royal E, Montreal, H2T 1N4 | F19: 45.520465 | G19: -73.586269 | I19: 5
A20: https://www.restomontreal.ca/resto/comptoir-barranco-cafe-sandwicherie-montreal/15035/en/
A21: Comptoir Barranco Café Sandwicherie | B21: $ | C21: 10 | D21: Master Card, Visa, AMEX, Interac | E21: 4552 Rue Saint-Denis, Montreal, H2J 2L3 | F21: 45.524197 | G21: -73.583993 | I21: 5
A22: https://www.restomontreal.ca/resto/birbante-montreal/19732/en/
A23: Birbante | B23: $$ & $$$ | C23: 31.25 | E23: 5386 Boulevard St-Laurent, Montreal, H2T 1S1 | F23: 45.524948 | G23: -73.59739 | I23: 5
A24: https://www.restomontreal.ca/resto/frite-alors-montreal/747/en/
A25: Frite Alors! | B25: $ | C25: 10 | D25: Master Card, Visa, Interac | E25: 433 Rue Rachel E, Montreal, H2J 2G8 | F25: 45.522375 | G25: -73.577919 | I25: 4.5
A26: https://www.restomontreal.ca/resto/bar-judinstrom-montreal/21167/en/
A27: Bar Judinstrom | B27: $$ | C27: 25 | D27: Master Card, Visa, AMEX, Interac, Mobile Payment, Contactless Payment | E27: 3922 Rue St-Denis, Montreal, H2W 2M2 | F27: 45.519903 | G27: -73.574364 | I27: 5
A28: https://www.restomontreal.ca/resto/la-banquise-montreal/2499/en/
A29: La Banquise | B29: $ & $$ | C29: 17.5 | D29: Interac, ATM machine | E29: 994 Rue Rachel E., Montreal, H2J 2J3 | F29: 45.525312 | G29: -73.574672 | I29: 4.5
A30: https://www.restomontreal.ca/resto/la-panzeria-montreal/15036/en/
A31: La Panzeria | B31: $ & $$ | C31: 17.5 | D31: Master Card, Visa, AMEX, Interac, Mobile Payment, Contactless Payment | E31: 4084 Rue Saint-Denis, Montreal, H2W 2M5 | F31: 45.520861 | G31: -73.576626 | I31: 5
A32: https://www.restomontreal.ca/resto/restaurant-manana-montreal/4996/en/
A33: Restaurant Manana | B33: $ | C33: 10 | D33: Master Card, Visa, AMEX, Interac | E33: 3605 Rue Saint-Denis, Montreal, H2X 3L6 | F33: 45.518002 | G33: -73.569333 | I33: 5
A34: https://www.restomontreal.ca/resto/artigiani-pizzeria-cucina-montreal/1889/en/
A35: Artigiani Pizzeria Cucina | B35: $ & $$ | C35: 17.5 | D35: Master Card, Visa, Interac | E35: 4657 Rue Saint-Denis, Montreal, H2J 2L5 | F35: 45.525016 | G35: -73.584779 | I35: 5
A36: https://www.restomontreal.ca/resto/india-rosa-plateau-montreal/12593/en/
A37: India Rosa Plateau | B37: $$ & $$$ | C37: 31.25 | D37: Master Card, Visa, AMEX, Interac, Mobile Payment, Contactless Payment | E37: 1241 Avenue Mont Royal E, Montreal, H2J 1Y2 | F37: 45.529253 | G37: -73.578392 | I37: 5
A38: https://www.restomontreal.ca/resto/balbastik-montreal/19518/en/
A39: Balbastik | B39: $ | C39: 10 | D39: Master Card, Visa, Interac, Mobile Payment | E39: 209 Avenue Fairmount O, Montreal, H2T 3E2 | F39: 45.521295 | G39: -73.597054 | I39: 5
A40: https://www.restomontreal.ca/resto/mirazu-montreal/12230/en/
...

Sheet Sheet8
A1: name | B1: price | C1: avg_price | D1: payment_type | E1: address | F1: lat | G1: long | H1: rating
A2: Caribou Gourmand | B2: $$ & $$$ | C2: 31.25 | D2: Master Card, Visa, Interac | E2: 5308 Boulevard St-Laurent, Montreal, H2T 1S1 | F2: 45.524438 | G2: -73.596378 | H2: 4.5
A3: Thailande | B3: $$ | C3: 25 | D3: Master Card, Visa, AMEX, Interac | E3: 88 Avenue Bernard O, Montreal, H2T 2J8 | F3: 45.526256 | G3: -73.602985 | H3: 4.5
A4: Joséphine | B4: $$ & $$$ | C4: 31.25 | D4: Master Card, Visa, AMEX, Interac | E4: 4007 Rue Saint-Denis, Montreal, H2W 2M4 | F4: 45.520846 | G4: -73.575569 | H4: 5
A5: Bistro CO ÚT | B5: $ & $$ | C5: 17.5 | D5: Master Card, Visa, AMEX, Interac | E5: 3807 Rue St-André, Montreal, H2L 3V9 | F5: 45.521892 | G5: -73.570211 | H5: 5
A6: La Belle Corée | B6: $ | C6: 10 | D6: Master Card, Visa, Interac | E6: 101 Avenue Fairmount O., Montreal, H2T 2M4 | F6: 45.52262 | G6: -73.595842 | H6: 4.5
A7: Sham Mont-Royal | B7: $$ | C7: 25 | D7: Master Card, Visa, AMEX, Interac, Mobile Payment, Contactless Payment | E7: 1371 Avenue Mont-Royal E, Montreal, H2J 1Y8 | F7: 45.530606 | G7: -73.577013 | H7: 5
A8: La Maison Grecque | B8: $$ | C8: 25 | D8: Master Card, Visa, Interac | E8: 450 Avenue Duluth E, Montreal, H2L 1A5 | F8: 45.521371 | G8: -73.575149 | H8: 4.5
A9: La Petite Marche | B9: $ & $$ | C9: 17.5 | D9: Master Card, Visa, Interac | E9: 5035 Rue Saint-Denis, Montreal, H2J 2L9 | F9: 45.526746 | G9: -73.588648 | H9: 4.5
A10: ZEEZ | B10: $ | C10: 10 | D10: Master Card, Visa, AMEX, Interac, Mobile Payment, Contactless Payment | E10: 19 Avenue Mont-Royal E, Montreal, H2T 1N4 | F10: 45.520465 | G10: -73.586269 | H10: 5
A11: Comptoir Barranco Café Sandwicherie | B11: $ | C11: 10 | D11: Master Card, Visa, AMEX, Interac | E11: 4552 Rue Saint-Denis, Montreal, H2J 2L3 | F11: 45.524197 | G11: -73.583993 | H11: 5
A12: Birbante | B12: $$ & $$$ | C12: 31.25 | E12: 5386 Boulevard St-Laurent, Montreal, H2T 1S1 | F12: 45.524948 | G12: -73.59739 | H12: 5
A13: Frite Alors! | B13: $ | C13: 10 | D13: Master Card, Visa, Interac | E13: 433 Rue Rachel E, Montreal, H2J 2G8 | F13: 45.522375 | G13: -73.577919 | H13: 4.5
A14: Bar Judinstrom | B14: $$ | C14: 25 | D14: Master Card, Visa, AMEX, Interac, Mobile Payment, Contactless Payment | E14: 3922 Rue St-Denis, Montreal, H2W 2M2 | F14: 45.519903 | G14: -73.574364 | H14: 5
A15: La Banquise | B15: $ & $$ | C15: 17.5 | D15: Interac, ATM machine | E15: 994 Rue Rachel E., Montreal, H2J 2J3 | F15: 45.525312 | G15: -73.574672 | H15: 4.5
A16: La Panzeria | B16: $ & $$ | C16: 17.5 | D16: Master Card, Visa, AMEX, Interac, Mobile Payment, Contactless Payment | E16: 4084 Rue Saint-Denis, Montreal, H2W 2M5 | F16: 45.520861 | G16: -73.576626 | H16: 5
A17: Restaurant Manana | B17: $ | C17: 10 | D17: Master Card, Visa, AMEX, Interac | E17: 3605 Rue Saint-Denis, Montreal, H2X 3L6 | F17: 45.518002 | G17: -73.569333 | H17: 5
A18: Artigiani Pizzeria Cucina | B18: $ & $$ | C18: 17.5 | D18: Master Card, Visa, Interac | E18: 4657 Rue Saint-Denis, Montreal, H2J 2L5 | F18: 45.525016 | G18: -73.584779 | H18: 5
A19: India Rosa Plateau | B19: $$ & $$$ | C19: 31.25 | D19: Master Card, Visa, AMEX, Interac, Mobile Payment, Contactless Payment | E19: 1241 Avenue Mont Royal E, Montreal, H2J 1Y2 | F19: 45.529253 | G19: -73.578392 | H19: 5
A20: Balbastik | B20: $ | C20: 10 | D20: Master Card, Visa, Interac, Mobile Payment | E20: 209 Avenue Fairmount O, Montreal, H2T 3E2 | F20: 45.521295 | G20: -73.597054 | H20: 5
A21: Mirazu | B21: $ & $$ | C21: 17.5 | D21: Master Card, Visa, Interac | E21: 5215 Boulevard St-Laurent, Montreal, H2T 1S4 | F21: 45.524138 | G21: -73.594818 | H21: 5
A22: Ohana Sushi Vegan | B22: $ | C22: 10 | D22: Master Card, Visa, Interac | E22: 330 Avenue Mont-Royal E, Montreal, H2T 1P8 | F22: 45.523238 | G22: -73.583334 | H22: 5
A23: Le RAVITO Café-Buvette | B23: $ & $$ | C23: 17.5 | E23: 4051 Rue St-Hubert, Montreal, H2L 4A7 | F23: 45.522635 | G23: -73.574298 | H23: 4.5
A24: Bistro GURU | B24: $$ & $$$ | C24: 31.25 | D24: =IFERROR(__xludf.DUMMYFUNCTION("IMPORTXML(#REF!,'URLs and Paths'!$B$5)"),"#REF!") -> #REF! | E24: 3464 Rue Saint-Denis, Montreal, H2X 3L3 | F24: 45.517267 | G24: -73.568705 | H24: 5
A25: Pamika Thai | B25: $$ | C25: 25 | E25: 4902 Boulevard St-Laurent, Montreal, H2T 1R5 | F25: 45.522149 | G25: -73.59111 | H25: 4.5
A26: BOCA Iberica | B26: $$ | C26: 25 | D26: Master Card, Visa, AMEX, Interac | E26: 12 Rue Rachel O, Montreal, H2W 1G1 | F26: 45.517576 | G26: -73.581772 | H26: 5
A27: Aux Lilas | B27: $ & $$ | C27: 17.5 | D27: Master Card, Visa, Interac | E27: 5570 Avenue du Parc, Montreal, H2V 4H1 | F27: 45.522282 | G27: -73.602832 | H27: 5
A28: Point Bar | B28: $ & $$ | C28: 17.5 | D28: Master Card, Visa, AMEX, Interac, Mobile Payment, Contactless Payment | E28: 2017 Rue St-Denis, Montreal, H2X 3K8 | F28: 45.516237 | G28: -73.565631 | H28: 4
A29: Saint Sushi | B29: $$ | C29: 25 | D29: Master Card, Visa, AMEX, Interac | E29: 424 Avenue Duluth E, Montreal, H2W 2M3 | F29: 45.521118 | G29: -73.575357 | H29: 5
A30: Resto Bar Nemo | B30: $ & $$ | C30: 17.5 | D30: Master Card, Visa, AMEX, Interac, Mobile Payment, Contactless Payment | E30: 64 Rue Prince-Arthur E, Montreal, H2X 1B3 | F30: 45.514488 | G30: -73.571846 | H30: 5
A31: McKibbins Irish Pub | B31: $ | C31: 10 | D31: Master Card, Visa, AMEX, Interac, ATM machine | E31: 3515 Boulevard St Laurent, Montreal, H2X 2T6 | F31: 45.513499 | G31: -73.571102 | H31: 4.5
A32: Rutba | B32: $$ | C32: 25 | E32: 3633 Boulevard St-Laurent, Montreal, H2X 2V5 | F32: 45.514378 | G32: -73.573165 | H32: 5
A33: El Lounge Resto-Bar | B33: $$ & $$$ | C33: 31.25 | D33: Master Card, Visa, AMEX, Interac, Mobile Payment, Contactless Payment | E33: 1735 Saint Denis St, Montreal, Quebec H2X 3K4 | F33: 45.515751 | G33: -73.564437 | H33: 5
A34: Mlle Rosa | B34: $$ & $$$ | C34: 31.25 | E34: 1233 Avenue Mont-Royal E, Montreal, H2J 1Y2 | F34: 45.529238 | G34: -73.578403 | H34: 4.5
A35: L'Évidence | B35: $ | C35: 10 | D35: Master Card, Visa, Interac | E35: 3817 Rue Saint-Denis, Montreal, H2W 2M4 | F35: 45.519634 | G35: -73.572848 | H35: 4.5
A36: Sandhu | B36: $$ | C36: 25 | D36: Master Card, Visa, AMEX, Interac, ATM machine | E36: 4548 Avenue Papineau, Montreal, H2H 1V3 | F36: 45.533167 | G36: -73.575574 | H36: 4.5
A37: Snatch Restaurant | B37: $ | C37: 10 | D37: Master Card, Visa, AMEX, Interac | E37: 4675 Boulevard St-Laurent, Montreal, H2T 1R2 | F37: 45.521527 | G37: -73.589125 | H37: 5
A38: Café buvette Magnolia | B38: $$ | C38: 25 | D38: Master Card, Visa, AMEX, Interac, Mobile Payment, Contactless Payment | E38: 187 Avenue Mont-Royal E, Montreal, H2T 1P2 | F38: 45.522117 | G38: -73.584829 | H38: 4.5
A39: La Selva Restaurant Mexicain | B39: $ | C39: 10 | D39: Master Card, Visa, AMEX, Interac | E39: 862 Rue Marie-Anne E, Montreal, H2J 2A9 | F39: 45.525193 | G39: -73.57817 | H39: 5
A40: Ibéricos Taverne à Tapas Espagnoles | B40: $ & $$ | C40: 17.5 | E40: 4475 Rue Saint-Denis, Montreal, H2J 2L2 | F40: 45.523935 | G40: -73.582341 | H40: 4.5
...
